Workbook

Sheet Natural and Forced Convection C
A1: Initial Inputs | E1: Forced Convection around Heat Sink | I1: Free/Natural Convection at Nozzle | M1: Free/Natural Convection at Top of Heat Block | Q1: Final Values for Convection Heat Transfer Coefficients
A3: Name | B3: Units | C3: Value | E3: Name | F3: Units | G3: Value | I3: Name | J3: Units | K3: Value | M3: Name | N3: Units | O3: Value | Q3: Name | R3: Units | S3: Value
A4: Fan Details | E4: Calculate AIrflow Rate | I4: Calculate Grashof's Number | M4: Calculate Grashof's Number | Q4: Convective Heat Transfer Coefficient
A5: Fan Airflow | B5: m^3/h | C5: 8.2 | E5: Fan Airflow | F5: m^3/s | G5: =C5/3600 -> 0.0022777778 | I5: Gravitational Acceleration (g) | J5: m/s^2 | K5: =C11 -> 9.81 | M5: Gravitational Acceleration (g) | N5: m/s^2 | O5: =C18 -> 9.81 | Q5: Natural Air at top of heat block | R5: W/m^2K | S5: =O34 -> 4.5045031
A6: Fan Diameter | B6: mm | C6: =37 -> 37 | E6: Fan Diameter | F6: m | G6: =C6/1000 -> 0.037 | I6: Surface Temperature (Ts) | J6: K | K6: =C12+273 -> 503 | M6: Surface Temperature (Ts) | N6: K | O6: =C19+273 -> 503 | Q6: Natural Air at bottom of nozzle | R6: W/m^2K | S6: =K34 -> 5.5195003
A7: Length of gap | B7: mm | C7: 7 | E7: Area of the fan | F7: m^2 | G7: =pi()*(G6/2)^2 -> 0.0010752101 | I7: Ambient Temperature (Tinfinity) | J7: K | K7: =C13+273 -> 295 | M7: Ambient Temperature (Tinfinity) | N7: K | O7: =C20+273 -> 295 | Q7: Forced Air (from Fan) | R7: W/m^2K | S7: =G33 -> 54.430806
A8: Width of gap | B8: mm | C8: 1 | E8: Length of gap | F8: m | G8: =C7/1000 -> 0.007 | I8: Volume Exansion Coefficient (beta) | J8: m^3/s | K8: =1/C34 -> 0.0025062657 | M8: Volume Exansion Coefficient (beta) | N8: m^3/s | O8: =1/C34 -> 0.0025062657 | S8: =AVERAGE(S5:S6) -> 5.0120017
A9: Number of rectangular gaps | B9: dimensonless | C9: 22 | E9: Width of gap | F9: m | G9: =C8/1000 -> 0.001 | I9: Inner Radius | J9: m | K9: =C14/1000 -> 0.001 | M9: Width of hotend | N9: m | O9: =C21/1000 -> 0.023
A10: Nozzle Properties (Assumed to be modeled as a cylinder) | E10: Total area of gaps | F10: m^2 | G10: =G9*G8*22 -> 0.000154 | I10: Outer Radius | J10: m | K10: =C15/1000 -> 0.0035 | M10: Depth of hotend | N10: m | O10: =C22/1000 -> 0.016
A11: Gravitational Acceleration (g) | B11: m/s^2 | C11: 9.81 | E11: Airflow rate | F11: m/s | G11: =G5/G7 * G7 /G10 -> 14.790765 | I11: Length | J11: m | K11: =C16/1000 -> 0.006 | M11: Heatbreak Outer Radius of Neck | N11: m | O11: =C23/1000 -> 0.00148
A12: Surface Temperature (Ts) | B12: C | C12: =230 -> 230 | E12: Calculate Prandtl's Number | I12: Cross-sectional Area (A) | J12: m^2 | K12: =pi()*(K10^2-K9^2) -> 3.5342917e-05 | M12: Cross-sectional Area (A) | N12: m^2 | O12: =O10*O9-pi()*(O11)^2 -> 0.00036111866
A13: Ambient Temperature (Tinfinity) | B13: C | C13: =22 -> 22 | E13: Air Kinematic Viscosity (nu) | F13: m^2/s | G13: =C42 -> 2.63002e-05 | I13: Perimeter (P) | J13: m | K13: =2*pi()*K9+2*pi()*K10 -> 0.028274334 | M13: Perimeter (P) | N13: m | O13: =2*(O10+O9)+2*pi()*O11 -> 0.087299114
A14: Inner Radius | B14: mm | C14: 1 | E14: Air Thermal Conductivity (k) | F14: W/mK | G14: =C43 -> 0.033724 | I14: Critical Length (Lc) | J14: m | K14: =K12/K13 -> 0.00125 | M14: Critical Length (Lc) | N14: m | O14: =O12/O13 -> 0.0041365672
A15: Outer Radius | B15: mm | C15: 3.5 | E15: Air Density (rho) | F15: kg/m^3 | G15: =C44 -> 0.873578 | I15: Air Kinematic Viscosity (nu) | J15: m^2/s | K15: =C42 -> 2.63002e-05 | M15: Air Kinematic Viscosity (nu) | N15: m^2/s | O15: =C46 -> 2.29662e-05
A16: Length | B16: mm | C16: 6 | E16: Air Specific Heat Coefficient (cp) | F16: J/kg K | G16: =C45*1000 -> 1013.9 | I16: Grashof's Number (Gr) | J16: Dimensionless | K16: =(K5*K8*(K6-K7)*(K14^3))/((K15^2)) -> 14.440139 | M16: Grashof's Number (Gr) | N16: Dimensionless | O16: =(O5*O8*(O6-O7)*(O14^3))/((O15^2)) -> 686.28013
A17: Heat Block Properties (Assumed to be modeled as a flat plate) | E17: Air Thermal Diffusivity (alpha) | F17: m^2/s | G17: =(G14)/(G15*G16) -> 3.8075207e-05 | I17: Calculate Prandtl's Number | M17: Calculate Prandtl's Number
A18: Gravitational Acceleration (g) | B18: m/s^2 | C18: =C11 -> 9.81 | E18: Prandtl's Number (Pr) | F18: Dimensionless | G18: =G13/G17 -> 0.69074346 | I18: Air Kinematic Viscosity (nu) | J18: m^2/s | K18: =C42 -> 2.63002e-05 | M18: Air Kinematic Viscosity (nu) | N18: m^2/s | O18: =C42 -> 2.63002e-05
A19: Surface Temperature (Ts) | B19: C | C19: =230 -> 230 | E19: Calculate Reynold's Number | I19: Thermal Conductivity (k) | J19: W/mK | K19: =C43 -> 0.033724 | M19: Thermal Conductivity (k) | N19: W/mK | O19: =C43 -> 0.033724
A20: Ambient Temperature (Tinfinity) | B20: C | C20: =22 -> 22 | E20: Air Density (rho) | F20: kg/m^3 | G20: =C44 -> 0.873578 | I20: Air Density (rho) | J20: kg/m^3 | K20: =C44 -> 0.873578 | M20: Air Density (rho) | N20: kg/m^3 | O20: =C44 -> 0.873578
A21: Width | B21: mm | C21: 23 | E21: Velocity (U) | F21: m/s | G21: =G11 -> 14.790765 | I21: Specific Heat Coefficient (cp) | J21: J/kg K | K21: =C45*1000 -> 1013.9 | M21: Specific Heat Coefficient (cp) | N21: J/kg K | O21: =C45*1000 -> 1013.9
A22: Depth | B22: mm | C22: 16 | E22: Characteristic length (i.e Diameter of the heatsink) | F22: m | G22: =(C28*2)/1000 -> 0.022 | I22: Air Thermal Diffusivity (alpha) | J22: m^2/s | K22: =(K19)/(K20*K21) -> 3.8075207e-05 | M22: Air Thermal Diffusivity (alpha) | N22: m^2/s | O22: =(O19)/(O20*O21) -> 3.8075207e-05
A23: Heatbreak Outer Radius of Neck | B23: mm | C23: 1.48 | E23: Dynamic viscosity (mu) | F23: kg/ms | G23: =C46 -> 2.29662e-05 | I23: Prandtl's Number (Pr) | J23: Dimensionless | K23: =K18/K22 -> 0.69074346 | M23: Prandtl's Number (Pr) | N23: Dimensionless | O23: =O18/O22 -> 0.69074346
A24: Length | B24: mm | C24: 11.5 | E24: Reynold's Number (Re) | F24: Dimensionless | G24: =(G20*G21*G22)/(G23) -> 12377.298 | I24: Calculate Rayleigh's Number | M24: Calculate Rayleigh's Number
A25: Heat Sink Dimensions (Modelled as Cylinder) | E25: Calculate the Nussult Number | I25: Rayleighs's Number (Ra) | J25: Dimensionless | K25: =K16*K23 -> 9.9744318 | M25: Rayleighs's Number (Ra) | N25: Dimensionless | O25: =O16*O23 -> 474.04351
A26: Inner Radius | B26: mm | C26: =average(2.1,3.5) -> 2.8 | E26: Assumptions | I26: Calculate the Nussult Number | M26: Calculate the Nussult Number
A27: Middle Radius | B27: mm | C27: 4 | E27: Geometry: | F27: Cylinder | I27: Assumptions | M27: Assumptions
A28: Outer Radius | B28: mm | C28: 11 | E28: Condition: | F28: Average, T_film,Re_D*Pr>= 0.2 | I28: Geometry: | J28: Long Horizontal Cylinder | M28: Geometry: | N28: Vertical Plate
A29: Length for Each Fin | B29: mm | C29: 1 | E29: Nussult Number (Nu) | F29: Dimensionless | G29: =0.3+(0.62*(G24^(1/2))*(G18^(1/3))*((1+(0.4/G18)^(2/3))^(-1/4))*((1+(G24/282000)^(5/8))^(4/5))) -> 59.718296 | I29: Formula | J29: Churchill and Chu Correlation | M29: Formula | N29: Churchill and Chu Correlation for Ra <= 10^9
A30: Length for Each Gap | B30: mm | C30: 1 | E30: Calculate the Heat Transfer Coefficient | I30: Nussult Number (Nu) | J30: Dimensionless | K30: =(0.6+((0.387*(K25)^(1/6))/(1+(0.559/K23)^(9/16))^(8/27)))^(2) -> 1.1456678 | M30: Nussult Number (Nu) | N30: Dimensionless | O30: =0.68+((0.67*(O25)^(1/4))/(1+(0.492/O23)^(9/16))^(4/9)) -> 3.0721021
A31: Film Temperature | E31: Characteristic length (i.e Diameter of the heatsink) | F31: m | G31: =C6/1000 -> 0.037 | I31: Calculate the Heat Transfer Coefficient | M31: Calculate the Heat Transfer Coefficient
A32: Surface Temperature (Ts) | B32: K | C32: =C19+273 -> 503 | E32: Thermal Conductivity (k) | F32: W/mK | G32: =C43 -> 0.033724 | I32: Characteristic length (i.e Outer Diameter of the Nozzle) | J32: m | K32: =C15*2/1000 -> 0.007 | M32: Length (L) | N32: m | O32: =O9 -> 0.023
A33: Ambient Temperature (Tinfinity) | B33: K | C33: =C20+273 -> 295 | E33: Convection Heat Transfer Coefficient (h) | F33: W/m^2K | G33: =G29*G32/G31 -> 54.430806 | I33: Thermal Conductivity (k) | J33: W/mK | K33: =C43 -> 0.033724 | M33: Thermal Conductivity (k) | N33: W/mK | O33: =C43 -> 0.033724
A34: Film Temperature | B34: K | C34: =AVERAGE(C32:C33) -> 399 | I34: Convection Heat Transfer Coefficient (h) | J34: W/m^2K | K34: =K30*K33/K32 -> 5.5195003 | M34: Convection Heat Transfer Coefficient (h) | N34: W/m^2K | O34: =O30*O33/O32 -> 4.5045031
A35: Air Properties at 22C OR 295K
A36: Air Kinematic Viscosity (nu) | B36: m^2/s | C36: 1.524e-05
A37: Air Thermal Conductivity (k) | B37: W/mK | C37: 0.02582
A38: Air Density (rho) | B38: kg/m^3 | C38: 1.196
A39: Air Specific Heat Coefficient (cp) | B39: kJ/kg K | C39: =1.006 -> 1.006
A40: Dynamic viscosity (mu) | B40: kg/ms | C40: 1.822e-05
A41: Air Properties at Film Temperature 126C OR 399K
...

Sheet Solution 7
A2: Initial Inputs | E2: Individiual Resistance | I2: Total Resistance | M2: Temperature at Different Points | Q2: Final Values Summary
A4: Name | B4: Units | C4: Value | E4: Name | F4: Units | G4: Value | I4: Name | J4: Units | K4: Value | M4: Name | N4: Units | O4: Value | Q4: Name | R4: Units | S4: Value
A5: Initial Temperatures | I5: Total Resistance through the Bottom | M5: Temperature at Bottom of Nozzle | Q5: Heat Balance
A6: Temperature of the Heater Cartridge | B6: C | C6: 230 | E6: In Series Convection and Conduction of Nozzle | I6: In Series Convection and Conduction of Nozzle outside heatblock | J6: K/W | K6: =G20 -> 5126.5236 | M6: Temperature of the Ambient Air | N6: K | O6: =C7+273 -> 295 | Q6: Total Heat In | R6: W | S6: =K77 -> 10.421814
A7: Temperature of the Ambient AIr | B7: C | C7: 22 | I7: In Parallel Conduction of Brass and Aluminium in Bottom Section of Heat Block | J7: K/W | K7: =G39 -> 0.063474577 | M7: Natural Convective Nozzle Resistance Outside of Heat Block | N7: K/W | O7: =G13 -> 5126.2271 | Q7: Total Heat Out through Bottom | R7: W | S7: =K50 -> 0.040572802 | T7: =S7+S8 -> 3.457974
A8: Thermal Conductivity | E8: Natural Convection Resistance between Nozzle and Ambient Air | I8: Total Bottom Resistance | J8: K/W | K8: =SUM(K6:K7) -> 5126.587 | M8: Total Bottom Heat Out | N8: W | O8: =K50 -> 0.040572802 | Q8: Total Heat Out through Top | R8: W | S8: =K55 -> 3.4174012
A9: Alumnium | B9: W/mK | C9: 155.3 | E9: Natural Convective Bottom Air Heat Transfer Coefficient | F9: W/m^2K | G9: =C14 -> 5.5195003 | I9: Total Resistance through the Top | M9: Bottom of Nozzle Temperature | N9: K | O9: =O6+O7*O8 -> 502.9854 | Q9: Total Heat Out through Filament | R9: W | S9: =K68 -> 6.96384
A10: Brass | B10: W/mK | C10: 112.1 | E10: Inner Radius | F10: m | G10: =C27/1000 -> 0.001 | I10: In Parallel Conduction of Brass and Aluminium in Middle Section of Heat Block | J10: K/W | K10: =G58 -> 0.044040127 | M10: Temperature at Bottom of Heat Block | Q10: Check | S10: =S6-SUM(S7:S9) -> 0
A11: Stainless Steel | B11: W/mK | C11: 14.58 | E11: Outer Radius | F11: m | G11: =C28/1000 -> 0.0035 | I11: In Parallel Conduction of Steel and Aluminium in Top Section of Heat Block | J11: K/W | K11: =G77 -> 0.091167601 | M11: Bottom of Nozzle Temperature | N11: K | O11: =O9 -> 502.9854
A12: Convective Heat Transfer Coefficient | E12: Area of nozzle | F12: m^2 | G12: =pi()*(G11^2-G10^2) -> 3.5342917e-05 | I12: In Parallel Conduction of Steel and Convection through neck of Heat Break 1 | J12: K/W | K12: =$G$95 -> 10.023208 | M12: Conductive Nozzle Resistance Outside of Heat Block | N12: K/W | O12: =G19 -> 0.29643684 | Q12: Name | R12: Units | S12: Value
A13: Natural Air at top of heat block | B13: W/m^2K | C13: ='Natural and Forced Convection C'!S5 -> 4.5045031 | E13: Natural Convective Nozzle Resistance Outside of Heat Block | F13: K/W | G13: =1/(G9*G12) -> 5126.2271 | I13: In Parallel Conduction of Steel and Convection through neck of Heat Break 2 | J13: K/W | K13: =$G$95 -> 10.023208 | M13: Total Bottom Heat Out | N13: W | O13: =K50 -> 0.040572802 | Q13: Temperature Values
A14: Natural Air at bottom of nozzle | B14: W/m^2K | C14: ='Natural and Forced Convection C'!S6 -> 5.5195003 | E14: Cylindrical Conduction Resistance of Nozzle | I14: In Parallel Conduction of Steel and Convection through neck of Heat Break 3 | J14: K/W | K14: =$G$95 -> 10.023208 | M14: Bottom of Heat Block Temperature | N14: K | O14: =O11+O12*O13 -> 502.99742 | Q14: Ambient Temperature | R14: C | S14: =C7 -> 22
A15: Forced Air (from Fan) | B15: W/m^2K | C15: ='Natural and Forced Convection C'!S7 -> 54.430806 | E15: Inner Radius | F15: m | G15: =C27/1000 -> 0.001 | I15: In Parallel Conduction of Steel and Convection through neck of Heat Break 4 | J15: K/W | K15: =$G$95 -> 10.023208 | Q15: Bottom of Nozzle Temperature | R15: C | S15: =O9-273 -> 229.9854
A16: PLA Properties | E16: Outer Radius | F16: m | G16: =C28/1000 -> 0.0035 | I16: In Parallel Conduction of Steel and Convection through neck of Heat Break 5 | J16: K/W | K16: =$G$95 -> 10.023208 | M16: Temperature at Top of Heat Sink - TF24 | Q16: Bottom of Heat Block Temperature | R16: C | S16: =O14-273 -> 229.99742
A17: Density of PLA | B17: kg/m^3 | C17: 1240 | E17: Length | F17: m | G17: =C29/1000 -> 0.006 | I17: In Parallel Conduction of Steel and Aluminium through each Fin 1 | J17: K/W | K17: =G129 -> 0.84788501 | M17: Temperature of the Ambient Air | N17: K | O17: =C7+273 -> 295 | Q17: Heater Cartridge Temperature | R17: C | S17: =C6 -> 230
A18: Estimated Volumetric Flow Rate of PLA | B18: mm^3/s | C18: 15 | E18: Thermal Conducitvity of Brass | F18: W/mK | G18: =C10 -> 112.1 | I18: In Parallel Condunction of Steel and Aluminium and Convection through Gap 1 | J18: K/W | K18: =G130 -> 0.00036551636 | M18: Heat Sink Resistance per Gap for top 6 | N18: K/W | O18: =K40 -> 0.00036552613 | Q18: Bottom of Heat Break Temperature | R18: C | S18: =O70-273 -> 229.8495
A19: Specific Heat Capacity of PLA | B19: J/kgK | C19: 1800 | E19: Conductive Nozzle Resistance Outside of Heat Block | F19: K/W | G19: =LN((G16/G15))/(2*pi()*G17*G18) -> 0.29643684 | I19: In Parallel Conduction of Steel and Aluminium through each Fin 2 | J19: K/W | K19: =G129 -> 0.84788501 | M19: Total Top Heat Out | N19: W | O19: =K55 -> 3.4174012 | Q19: Top of Heat Block Temperature | R19: C | S19: =O65-273 -> 229.53794
A20: Temperature of unheated PLA | B20: C | C20: 22 | E20: In Series Convection and Conduction of Nozzle outside heatblock | G20: =G13+G19 -> 5126.5236 | I20: In Parallel Condunction of Steel and Aluminium and Convection through Gap 2 | J20: K/W | K20: =G130 -> 0.00036551636 | M20: Top of Heat Sink Temperature - TF24 | N20: K | O20: =O17+O18*O19 -> 295.00125 | Q20: THB 2 | S20: =O59-273 -> 195.28462
A21: Temperature of heated PLA | B21: C | C21: 230 | I21: In Parallel Conduction of Steel and Aluminium through each Fin 3 | J21: K/W | K21: =G129 -> 0.84788501 | Q21: THB 3 | S21: =O58-273 -> 161.03129
E22: In Parallel Conduction of Brass and Aluminium in Bottom Section of Heat Block | I22: In Parallel Condunction of Steel and Aluminium and Convection through Gap 3 | J22: K/W | K22: =G130 -> 0.00036551636 | M22: Temperature of all the Fins | Q22: THB 4 | S22: =O57-273 -> 126.77797
A23: Dimensions | I23: In Parallel Conduction of Steel and Aluminium through each Fin 4 | J23: K/W | K23: =G129 -> 0.84788501 | M23: Heat Sink Resistance per Fin for Top 5 | N23: K/W | O23: =K39 -> 0.93482664 | Q23: THB 5 | S23: =O56-273 -> 92.524645
E24: Cylindrical Conduction Resistance of Brass in Heat Block | I24: In Parallel Condunction of Steel and Aluminium and Convection through Gap 4 | J24: K/W | K24: =G130 -> 0.00036551636 | M24: Heat Sink Resistance per Gap for Top 6 | N24: K/W | O24: =K40 -> 0.00036552613 | Q24: TF1 - Bottom of Heat Sink | R24: C | S24: =O51-273 -> 58.27132
A25: Name | B25: Units | C25: Value | E25: Inner Radius | F25: m | G25: =C31/1000 -> 0.001 | I25: In Parallel Conduction of Steel and Aluminium through each Fin 5 | J25: K/W | K25: =G129 -> 0.84788501 | M25: Heat Sink Resistance per Fin for Top 7 | N25: K/W | O25: =K29 -> 0.84788501 | Q25: TF2 | R25: C | S25: =O50-273 -> 55.373757
A26: Nozzle Dimensions Outside of Heat Block (Modelled as Cylinder) | E26: Outer Radius | F26: m | G26: =C32/1000 -> 0.003 | I26: In Parallel Condunction of Steel and Aluminium and Convection through Gap 5 | J26: K/W | K26: =G130 -> 0.00036551636 | M26: Heat Sink Resistance per Gap for Top 6 | N26: K/W | O26: =K28 -> 0.00036551636 | Q26: TF3 | R26: C | S26: =O49-273 -> 55.372508
A27: Inner Radius | B27: mm | C27: 1 | E27: Length of bottom section | F27: m | G27: =C37/1000 -> 0.004 | I27: In Parallel Conduction of Steel and Aluminium through each Fin 6 | J27: K/W | K27: =G129 -> 0.84788501 | M27: Total Top Heat Out | N27: W | O27: =K55 -> 3.4174012 | Q27: TF4 | R27: C | S27: =O48-273 -> 52.474945
A28: Outer Radius | B28: mm | C28: 3.5 | E28: Thermal Conducitvity of Brass | F28: W/mK | G28: =C10 -> 112.1 | I28: In Parallel Condunction of Steel and Aluminium and Convection through Gap 6 | J28: K/W | K28: =G130 -> 0.00036551636 | M28: Top of Heat Sink Temperature - TF24 | N28: K | O28: =O20 -> 295.00125 | Q28: TF5 | R28: C | S28: =O47-273 -> 52.473696
A29: Length | B29: mm | C29: 6 | E29: Conductive Brass Resistance in Bottom Section Heat Block | F29: K/W | G29: =LN((G26/G25))/(2*pi()*G27*G28) -> 0.38994107 | I29: In Parallel Conduction of Steel and Aluminium through each Fin 7 | J29: K/W | K29: =G129 -> 0.84788501 | M29: TF23 | N29: K | O29: =O28+$O$27*$O$23 -> 298.19593 | P29: F12 | Q29: TF6 | R29: C | S29: =O46-273 -> 49.576133
A30: Nozzle Dimensions Inside of Heat Block (Modelled as Cylindrer) | E30: Flat Plate Conduction Resistance of aluminium bottom half of heat block | I30: In Parallel Conduction of Aluminium and Convection through the Gap 7 | J30: K/W | K30: =G132 -> 0.00036552613 | M30: TF22 | N30: K | O30: =O29+$O$27*$O$24 -> 298.19718 | Q30: TF7 | R30: C | S30: =O45-273 -> 49.574883
A31: Inner Radius | B31: mm | C31: 1 | E31: Thermal Conducitvity of Aluminium | F31: W/mK | G31: =C9 -> 155.3 | I31: Conduction of Aluminium through Fin 8 | J31: K/W | K31: =G131 -> 0.93482664 | M31: TF21 | N31: K | O31: =O30+$O$27*$O$23 -> 301.39185 | P31: F11 | Q31: TF8 | R31: C | S31: =O44-273 -> 46.67732
A32: Outer Radius | B32: mm | C32: 3 | E32: Length of bottom section | F32: m | G32: =C37/1000 -> 0.004 | I32: In Parallel Conduction of Aluminium and Convection through the Gap 8 | J32: K/W | K32: =G132 -> 0.00036552613 | M32: TF20 | N32: K | O32: =O31+$O$27*$O$24 -> 301.3931 | Q32: TF9 | R32: C | S32: =O43-273 -> 46.676071
A33: Heat Block Dimensions (Modelled as Flat Plate) | E33: Width | F33: m | G33: =C35/1000 -> 0.023 | I33: Conduction of Aluminium through Fin 9 | J33: K/W | K33: =G131 -> 0.93482664 | M33: TF19 | N33: K | O33: =O32+$O$27*$O$23 -> 304.58778 | P33: F10 | Q33: TF10 | R33: C | S33: =O42-273 -> 43.778508
A34: Cross-sectional Area Values (we will need to minus the area from the nozzle/heat break hole) | E34: Depth | F34: m | G34: =C36/1000 -> 0.016 | I34: In Parallel Conduction of Aluminium and Convection through the Gap 9 | J34: K/W | K34: =G132 -> 0.00036552613 | M34: TF18 | N34: K | O34: =O33+$O$27*$O$24 -> 304.58903 | Q34: TF11 | R34: C | S34: =O41-273 -> 43.777259 | U34: Distribution of Heat Through Heatblock and Nozzle | Z34: Distribution of Heat Through Heatbreak Neck | AF34: Distribution of Heat Through Heat Sink
A35: Width | B35: mm | C35: 23 | E35: Area of Rectangle | F35: m^2 | G35: =G34*G33 -> 0.000368 | I35: Conduction of Aluminium through Fin 10 | J35: K/W | K35: =G131 -> 0.93482664 | M35: TF17 | N35: K | O35: =O34+$O$27*$O$23 -> 307.78371 | P35: F9 | Q35: TF12 | R35: C | S35: =O40-273 -> 40.879696 | U35: Distance from the top (mm) | V35: Temperature (°C) | Z35: Distance from bottom of heat sink (mm) | AA35: Temperature (°C) | AF35: Distance from bottom of top of heat sink (mm) | AG35: Temperature (°C)
A36: Depth | B36: mm | C36: 16 | E36: Area of Cylinder | F36: m^2 | G36: =pi()*(G26)^2 -> 2.8274334e-05 | I36: In Parallel Conduction of Aluminium and Convection through the Gap 10 | J36: K/W | K36: =G132 -> 0.00036552613 | M36: TF16 | N36: K | O36: =O35+$O$27*$O$24 -> 307.78496 | Q36: TF13 | R36: C | S36: =O39-273 -> 40.878446 | U36: =0 -> 0 | V36: =S19 -> 229.53794 | Z36: 0 | AA36: =S24 -> 58.27132 | AF36: 0 | AG36: =S47 -> 22.001249
A37: Length of bottom section | B37: mm | C37: 4 | E37: Actual Area | F37: m^2 | G37: =G35-G36 -> 0.00033972567 | I37: Conduction of Aluminium through Fin 11 | J37: K/W | K37: =G131 -> 0.93482664 | M37: TF15 | N37: K | O37: =O36+$O$27*$O$23 -> 310.97963 | P37: F8 | Q37: TF14 | R37: C | S37: =O38-273 -> 37.980883 | U37: =C39 -> 5 | V37: =S18 -> 229.8495 | Z37: =C46 -> 0.42 | AA37: =S23 -> 92.524645 | AF37: =C55 -> 1.5 | AG37: =S46 -> 25.195927
A38: Length of middle section | B38: mm | C38: 2.5 | E38: Conductive Aluminium Resistance in Bottom Section Heat Block | F38: K/W | G38: =G32/(G31*G37) -> 0.075815879 | I38: In Parallel Conduction of Aluminium and Convection through the Gap 11 | J38: K/W | K38: =G132 -> 0.00036552613 | M38: TF14 | N38: K | O38: =O37+$O$27*$O$24 -> 310.98088 | Q38: TF15 | R38: C | S38: =O37-273 -> 37.979634 | U38: =U37+C38 -> 7.5 | V38: =S17 -> 230 | Z38: =Z37+C46 -> 0.84 | AA38: =S22 -> 126.77797 | AF38: =AF37+C56 -> 2.5 | AG38: =S45 -> 25.197176
A39: Length of top section | B39: mm | C39: 5 | E39: In Parallel Conduction of Brass and Aluminium in Bottom Section of Heat Block | G39: =((1/G29)+(1/G38))^(-1) -> 0.063474577 | I39: Conduction of Aluminium through Fin 12 | J39: K/W | K39: =G131 -> 0.93482664 | M39: TF13 | N39: K | O39: =O38+$O$27*$O$25 -> 313.87845 | P39: F7 | Q39: TF16 | R39: C | S39: =O36-273 -> 34.784956 | U39: =U38+C37 -> 11.5 | V39: =S16 -> 229.99742 | Z39: =Z38+C46 -> 1.26 | AA39: =S21 -> 161.03129 | AF39: =AF38+C55 -> 4 | AG39: =S44 -> 28.391854
A40: Heat Break Dimensions Inside of Heat Block (Modelled as Flat Plate but Cylindrical Area) | I40: In Parallel Conduction of Aluminium and Convection through the Gap 12 | J40: K/W | K40: =G132 -> 0.00036552613 | M40: TF12 | N40: K | O40: =O39+$O$27*$O$26 -> 313.8797 | Q40: TF17 | R40: C | S40: =O35-273 -> 34.783707 | U40: =U39+C29 -> 17.5 | V40: =S15 -> 229.9854 | Z40: =Z39+C46 -> 1.68 | AA40: =S20 -> 195.28462 | AF40: =AF39+C56 -> 5 | AG40: =S43 -> 28.393103
A41: Inner Radius | B41: mm | C41: 1 | E41: In Parallel Conduction of Brass and Aluminium in Middle Section of Heat Block | I41: Total Top Resistance | J41: K/W | K41: =SUM(K10:K40) -> 60.864964 | M41: TF11 | N41: K | O41: =O40+$O$27*$O$25 -> 316.77726 | P41: F6 | Q41: TF18 | R41: C | S41: =O34-273 -> 31.58903 | Z41: =Z40+C46 -> 2.1 | AA41: =S19 -> 229.53794 | AF41: =AF40+C55 -> 6.5 | AG41: =S42 -> 31.58778
A42: Outer Radius | B42: mm | C42: 3 | M42: TF10 | N42: K | O42: =O41+$O$27*$O$26 -> 316.77851 | Q42: TF19 | R42: C | S42: =O33-273 -> 31.58778 | AF42: =AF41+C56 -> 7.5 | AG42: =S41 -> 31.58903
...

Sheet Heat Break Performance
A3: Distance from bottom of heat break (mm) | B3: Distance from bottom of heat break (mm) | C3: Temperature (deg Celcius) | E3: Distance from bottom of hotend (mm) | F3: Temperature (°C)
A4: 0 | B4: =A4*1000 -> 0 | C4: 229.12 | E4: 0 | F4: 229.8495
A5: 0.00046042 | B5: =A5*1000 -> 0.46042 | C5: 228.9 | E5: 5 | F5: 229.53794
A6: 0.00092083 | B6: =A6*1000 -> 0.92083 | C6: 228.57 | E6: 5.42 | F6: 195.28462
A7: 0.0013812 | B7: =A7*1000 -> 1.3812 | C7: 228.12 | E7: 5.84 | F7: 161.03129
A8: 0.0018417 | B8: =A8*1000 -> 1.8417 | C8: 227.49 | E8: 6.26 | F8: 126.77797
A9: 0.0023021 | B9: =A9*1000 -> 2.3021 | C9: 226.66 | E9: 6.68 | F9: 92.524645
A10: 0.0027625 | B10: =A10*1000 -> 2.7625 | C10: 225.83 | E10: 7.1 | F10: 58.27132
A11: 0.0032229 | B11: =A11*1000 -> 3.2229 | C11: 224.1 | E11: 8.6 | F11: 55.373757
A12: 0.0036833 | B12: =A12*1000 -> 3.6833 | C12: 221.29 | E12: 9.6 | F12: 55.372508
A13: 0.0041437 | B13: =A13*1000 -> 4.1437 | C13: 215.5 | E13: 11.1 | F13: 52.474945
A14: 0.0046042 | B14: =A14*1000 -> 4.6042 | C14: 205.77 | E14: 12.1 | F14: 52.473696
A15: 0.0050646 | B15: =A15*1000 -> 5.0646 | C15: 190.05 | E15: 13.6 | F15: 49.576133
... A23: 0.0087479 | B23: =A23*1000 -> 8.7479 | C23: 53.027 | E23: 23.6 | F23: 37.980883
A24: 0.0092083 | B24: =A24*1000 -> 9.2083 | C24: 50.594
A25: 0.0096688 | B25: =A25*1000 -> 9.6688 | C25: 49.517
A26: 0.010129 | B26: =A26*1000 -> 10.129 | C26: 48.296
A27: 0.01059 | B27: =A27*1000 -> 10.59 | C27: 47.246
A28: 0.01105 | B28: =A28*1000 -> 11.05 | C28: 46.384
A29: 0.01151 | B29: =A29*1000 -> 11.51 | C29: 45.732
A30: 0.011971 | B30: =A30*1000 -> 11.971 | C30: 45.294
A31: 0.012431 | B31: =A31*1000 -> 12.431 | C31: 44.901
A32: 0.012892 | B32: =A32*1000 -> 12.892 | C32: 44.525
A33: 0.013352 | B33: =A33*1000 -> 13.352 | C33: 44.18
A34: 0.013813 | B34: =A34*1000 -> 13.813 | C34: 43.872
A35: 0.014273 | B35: =A35*1000 -> 14.273 | C35: 43.602
... A52: 0.0221 | B52: =A52*1000 -> 22.1 | C52: 42.875

Sheet Solution 0
A3: Forced Convection around Heat Sink | E3: Free/Natural Convection around the Heat Block | I3: Conduction from heat cartridge to heat block
A5: Name | B5: Units | C5: Value | E5: Name | F5: Units | G5: Value | I5: Name | J5: Units | K5: Value
A6: Calculate AIrflow Rate | E6: Calculate Grashof's Number | I6: Calculate Heat Input Required
A7: Fan Airflow | B7: m^3/h | C7: 8.2 | E7: Gravitational Acceleration (g) | F7: m/s^2 | G7: 9.81 | I7: Width (W) | J7: m | K7: =23/1000 -> 0.023
A8: Fan Airflow | B8: m^3/s | C8: =C7/3600 -> 0.0022777778 | E8: Volume Exansion Coefficient (beta) | F8: m^3/s | G8: =1/AVERAGE(G9:G10) -> 0.0025062657 | I8: Depth (D) | J8: m | K8: =16/1000 -> 0.016
A9: Fan Diameter | B9: m | C9: =37/1000 -> 0.037 | E9: Surface Temperature (Ts) | F9: K | G9: =230+273 -> 503 | I9: Cross-sectional Area (A) | J9: m^2 | K9: =K8*K7 -> 0.000368
A10: Area of the fan | B10: m^2 | C10: =pi()*(C9/2)^2 -> 0.0010752101 | E10: Ambient Temperature (Tinfinity) | F10: K | G10: =22+273 -> 295 | I10: Thermal Conductivity of Aluminium (k) | J10: W/mK | K10: 155.3
A11: Airflow rate | B11: m/s | C11: =C8/C10 -> 2.118449 | E11: Length of hotend (L) | F11: m | G11: =23/1000 -> 0.023 | I11: Convection Heat Transfer Coefficient (h) | J11: W/m^2K | K11: =G35 -> 8.8768176
A12: Calculate Prandtl's Number | E12: Width of hotend (W) | F12: m | G12: =16/1000 -> 0.016 | I12: Length to top of heat block from heat cartridge (Lt) | J12: m | K12: =7.5/1000 -> 0.0075
A13: Air Kinematic Viscosity (nu) | B13: m^2/s | C13: 1.524e-05 | E13: Cross-sectional Area (A) | F13: m^2 | G13: =G12*G11 -> 0.000368 | I13: Length to bottom of heat block from heat cartridge (Lb) | J13: m | K13: =4/1000 -> 0.004
A14: Thermal Conductivity (k) | B14: W/mK | C14: 0.02582 | E14: Perimeter (P) | F14: m | G14: =2*(G12+G11) -> 0.078 | I14: Resistance to bottom cond (Rbcd) | J14: K/W | K14: =K13/(K10*K9) -> 0.069990761
A15: Air Density (rho) | B15: kg/m^3 | C15: 1.196 | E15: Critical Length (Lc) | F15: m | G15: =G13/G14 -> 0.0047179487 | I15: Resistance to bottom conv (Rbcv) | J15: K/W | K15: =1/(K11*K9) -> 306.12224
A16: Specific Heat Coefficient (cp) | B16: J/kg K | C16: =1.006*1000 -> 1006 | E16: Air Kinematic Viscosity (nu) | F16: m^2/s | G16: =C13 -> 1.524e-05 | I16: Resistance to top cond (Rtcd) | J16: K/W | K16: =K12/(K10*K9) -> 0.13123268
A17: Air Thermal Diffusivity (alpha) | B17: m^2/s | C17: =(C14)/(C15*C16) -> 2.145987e-05 | E17: Grashof's Number (Gr) | F17: Dimensionless | G17: =(G7*G8*(G9-G10)*(G15^3))/((G16^2)) -> 2312.3265 | I17: Resistance to top conv (Rtcv) | J17: K/W | K17: =K15 -> 306.12224
A18: Prandtl's Number (Pr) | B18: Dimensionless | C18: =C13/C17 -> 0.71016275 | E18: Calculate Prandtl's Number | I18: Total Resistance to bottom air (Rb) | J18: K/W | K18: =K14+K15 -> 306.19223
A19: Calculate Reynold's Number | E19: Air Kinematic Viscosity (nu) | F19: m^2/s | G19: =C13 -> 1.524e-05 | I19: Total Resistance to top air (Rt) | J19: K/W | K19: =K16+K17 -> 306.25348
A20: Air Density (rho) | B20: kg/m^3 | C20: =C15 -> 1.196 | E20: Thermal Conductivity (k) | F20: W/mK | G20: =C14 -> 0.02582 | I20: Temperature of heat cartridge (T_hc) | J20: K | K20: =230+273 -> 503
A21: Velocity (U) | B21: m/s | C21: =C11 -> 2.118449 | E21: Air Density (rho) | F21: kg/m^3 | G21: =C15 -> 1.196 | I21: Ambient Temperature (Tinfinity) | J21: K | K21: =22+273 -> 295
A22: Diameter (D) | B22: m | C22: =C9 -> 0.037 | E22: Specific Heat Coefficient (cp) | F22: J/kg K | G22: =C16 -> 1006 | I22: Heat Output through the bottom (Qbot) | J22: W | K22: =((K20-K21)/(K18)) -> 0.67931181
A23: Dynamic viscosity (mu) | B23: kg/ms | C23: 1.822e-05 | E23: Air Thermal Diffusivity (alpha) | F23: m^2/s | G23: =C17 -> 2.145987e-05 | I23: Heat Output through the top (Qtop) | J23: W | K23: =((K20-K21)/(K19)) -> 0.67917596
A24: Reynold's Number (Re) | B24: Dimensionless | C24: =(C15*C21*C22)/(C23) -> 5145.2035 | E24: Prandtl's Number (Pr) | F24: Dimensionless | G24: =G19/G23 -> 0.71016275 | I24: Heat Input (Q) | J24: W | K24: =SUM(K22:K23) -> 1.3584878
A25: Calculate the Nussult Number | E25: Calculate Rayleigh's Number | I25: Calculate the temperature at the top and bottom surface of the heat block
A26: Assumptions | E26: Rayleighs's Number (Ra) | F26: Dimensionless | G26: =G17*G24 -> 1642.1282 | I26: Temperature at the bottom of the hot end | J26: K | K26: =K20-K22*K14 -> 502.95245
A27: Geometry: | B27: Cylinder | E27: Calculate the Nussult Number | I27: Temperature at the top of the hot end | J27: K | K27: =K20-K23*K16 -> 502.91087
A28: Condition: | B28: Average, T_film,Re_D*Pr>= 0.2 | E28: Assumptions | I28: Calculate the temperature gradient from the heat cartridge to the bottom
A29: Nussult Number (Nu) | B29: Dimensionless | C29: =0.3+(0.62*(C24^(1/2))*(C18^(1/3))*((1+(0.4/C18)^(2/3))^(-1/4))*((1+(C24/282000)^(5/8))^(4/5))) -> 37.40507 | E29: Geometry: | F29: Vertical Plate | I29: Temp at Heat Catridge | J29: K | K29: =K20 -> 503
A30: Calculate the Heat Transfer Coefficient | E30: Formula | F30: Churchill and Chu Correlation for Ra <= 10^9 | I30: Temp at bottom of hotend | J30: K | K30: =K26 -> 502.95245
A31: Diameter (D) | B31: m | C31: =C9 -> 0.037 | E31: Nussult Number (Nu) | F31: Dimensionless | G31: =0.68+((0.67*(G26)^(1/4))/(1+(0.492/G24)^(9/16))^(4/9)) -> 3.9536562 | I31: Distance | J31: m | K31: =K13 -> 0.004
A32: Thermal Conductivity (k) | B32: W/mK | C32: =C14 -> 0.02582 | E32: Calculate the Heat Transfer Coefficient | I32: Rate of change | J32: K/m | K32: =(K29-K30)/K31 -> 11.886388
A33: Convection Heat Transfer Coefficient (h) | B33: W/m^2K | C33: =C29*C32/C31 -> 26.102673 | E33: Length (L) | F33: m | G33: =G11/2 -> 0.0115 | I33: Calculate the temperature gradient from the heat cartridge to the top
E34: Thermal Conductivity (k) | F34: W/mK | G34: =C32 -> 0.02582 | I34: Temp at Heat Catridge | J34: K | K34: =K20 -> 503
E35: Convection Heat Transfer Coefficient (h) | F35: W/m^2K | G35: =G31*G34/G33 -> 8.8768176 | I35: Temp at top of hotend | J35: K | K35: =K27 -> 502.91087
I36: Distance | J36: m | K36: =K12 -> 0.0075
I37: Rate of change | J37: K/m | K37: =(K34-K35)/K36 -> 11.884011
I39: Distance (m) | J39: Temperature
I40: 0 | J40: =K29 -> 503
I41: 0.0005 | J41: =$K$29-$K$32*I41 -> 502.99406
I42: 0.001 | J42: =$K$29-$K$32*I42 -> 502.98811
I43: 0.0015 | J43: =$K$29-$K$32*I43 -> 502.98217
I44: 0.002 | J44: =$K$29-$K$32*I44 -> 502.97623
...

Sheet Solution 1
A2: Initial Inputs | E2: Individiual Resistance | I2: Total Resistance | M2: Temperature at Different Points | Q2: Final Values Summary
A4: Name | B4: Units | C4: Value | E4: Name | F4: Units | G4: Value | I4: Name | J4: Units | K4: Value | M4: Name | N4: Units | O4: Value | Q4: Name | R4: Units | S4: Value
A5: Initial Temperatures | E5: Natural Convection Resistance between Nozzle and Ambient Air | I5: Total Resistance through the Bottom | M5: Temperature at Bottom of Nozzle | Q5: Heat Balance
A6: Temperature of the Heater Cartridge | B6: C | C6: 230 | E6: Natural Convective Air Heat Transfer Coefficient | F6: W/m^2K | G6: =C13 -> 5.5195003 | I6: Convective Nozzle Resistance | J6: K/W | K6: =G10 -> 5126.2271 | M6: Temperature of the Ambient Air | N6: K | O6: =C7+273 -> 295 | Q6: Total Heat In | R6: W | S6: =K51 -> 9.5913783
A7: Temperature of the Ambient AIr | B7: C | C7: 22 | E7: Inner Radius | F7: m | G7: =C26/1000 -> 0.001 | I7: Conductive Nozzle Resistance | J7: K/W | K7: =G16 -> 0.29643684 | M7: Convective Nozzle Resistance | N7: K/W | O7: =G10 -> 5126.2271 | Q7: Total Heat Out through Bottom | R7: W | S7: =K24 -> 0.04057275
A8: Thermal Conductivity | E8: Outer Radius | F8: m | G8: =C27/1000 -> 0.0035 | I8: Conductive bottom half of heat block resistance | J8: K/W | K8: =G23 -> 0.069990761 | M8: Total Bottom Heat Out | N8: W | O8: =K24 -> 0.04057275 | Q8: Total Heat Out through Top | R8: W | S8: =K29 -> 3.8592056
A9: Alumnium | B9: W/mK | C9: 155.3 | E9: Area of nozzle | F9: m^2 | G9: =pi()*(G8^2-G7^2) -> 3.5342917e-05 | I9: Total Bottom Resistance | J9: K/W | K9: =SUM(K6:K8) -> 5126.5935 | M9: Bottom of Nozzle Temperature | N9: K | O9: =O6+O7*O8 -> 502.98513 | Q9: Total Heat Out through Filament | R9: W | S9: =K42 -> 5.6916
A10: Brass | B10: W/mK | C10: 112.1 | E10: Convective Nozzle Resistance | F10: K/W | G10: =1/(G6*G9) -> 5126.2271 | I10: Total Resistance through the Top | M10: Temperature at Bottom of Heat Block | Q10: Check | S10: =S6-SUM(S7:S9) -> 0
A11: Stainless Steel | B11: W/mK | C11: 14.58 | E11: Cylindrical Conduction Resistance of Nozzle | I11: Conductive top half of heat block resistance | J11: K/W | K11: =G30 -> 0.13123268 | M11: Bottom of Nozzle Temperature | N11: K | O11: =O9 -> 502.98513
A12: Convective Heat Transfer Coefficient | E12: Inner Radius | F12: m | G12: =C26/1000 -> 0.001 | I12: Conductive Heat Break Resistance | J12: K/W | K12: =G36 -> 2.0378678 | M12: Conductive Nozzle Resistance | N12: K/W | O12: =G16 -> 0.29643684 | Q12: Name | R12: Units | S12: Value
A13: Natural Air at bottom of nozzle | B13: W/m^2K | C13: ='Natural and Forced Convection C'!S6 -> 5.5195003 | E13: Outer Radius | F13: m | G13: =C27/1000 -> 0.0035 | I13: Conductive Heat Sink Resistance | J13: K/W | K13: =G42 -> 0.049201402 | M13: Total Bottom Heat Out | N13: W | O13: =K24 -> 0.04057275 | Q13: Temperature Values
A14: Forced Air (from Fan) | B14: W/m^2K | C14: ='Natural and Forced Convection C'!S7 -> 54.430806 | E14: Length | F14: m | G14: =C28/1000 -> 0.006 | I14: Convective Heat Sink Resistance | J14: K/W | K14: =G48 -> 51.678801 | M14: Bottom of Heat Block Temperature | N14: K | O14: =O11+O12*O13 -> 502.99716 | Q14: Ambient Temperature | R14: C | S14: =C7 -> 22
A15: PLA Properties | E15: Thermal Conducitvity of Brass | F15: W/mK | G15: =C10 -> 112.1 | I15: Total Top Resistance | J15: K/W | K15: =SUM(K11:K14) -> 53.897103 | Q15: Bottom of Nozzle Temperature | R15: C | S15: =O9-273 -> 229.98513
A16: Density of PLA | B16: kg/m^3 | C16: 1240 | E16: Conductive Nozzle Resistance | F16: K/W | G16: =LN((G13/G12))/(2*pi()*G14*G15) -> 0.29643684 | M16: Temperature at Top of Heat Sink | Q16: Bottom of Heat Block Temperature | R16: C | S16: =O14-273 -> 229.99716
A17: Estimated Volumetric Flow Rate of PLA | B17: mm^3/s | C17: 15 | E17: Flat Plate Conduction Resistance of bottom half of heat block | I17: Total Heat Out (except Filament) | M17: Temperature of the Ambient Air | N17: K | O17: =C7+273 -> 295 | Q17: Heater Cartridge Temperature | R17: C | S17: =C6 -> 230
A18: Specific Heat Capacity of PLA | B18: J/kgK | C18: 1800 | E18: Thermal Conducitvity of Aluminium | F18: W/mK | G18: =C9 -> 155.3 | M18: Convective Heat Sink Resistance | N18: K/W | O18: =G48 -> 51.678801 | Q18: Top of Heat Block Temperature | R18: C | S18: =O30-273 -> 229.49355
A19: Temperature of unheated PLA | B19: C | C19: 60 | E19: Length | F19: m | G19: =C34/1000 -> 0.004 | I19: Name | J19: Units | K19: Value | M19: Total Top Heat Out | N19: W | O19: =K29 -> 3.8592056 | Q19: Bottom of Heat Sink Temperature | R19: C | S19: =O25-273 -> 221.629
A20: Temperature of heated PLA | B20: C | C20: 230 | E20: Width | F20: m | G20: =C31/1000 -> 0.023 | I20: Total Heat Out through the Bottom | M20: Top of Heat Sink Temperature | N20: K | O20: =O17+O18*O19 -> 494.43912 | Q20: Top of Heat Sink Temperature | R20: C | S20: =O20-273 -> 221.43912
E21: Depth | F21: m | G21: =C32/1000 -> 0.016 | I21: Temperature of the Heater Cartridge | J21: K | K21: =C6+273 -> 503 | M21: Temperature at Bottom of Heat Sink | Q21: Ambient Temperature | R21: C | S21: =C7 -> 22
A22: Dimensions | E22: Area | F22: m^2 | G22: =G21*G20 -> 0.000368 | I22: Temperature of the Ambient Air | J22: K | K22: =C7+273 -> 295 | M22: Top of Heat Sink Temperature | N22: K | O22: =O20 -> 494.43912
E23: Conductive bottom half of heat block resistance | F23: K/W | G23: =G19/(G18*G22) -> 0.069990761 | I23: Total Bottom Resistance | J23: K/W | K23: =K9 -> 5126.5935 | M23: Conductive Heat Sink Resistance | N23: K/W | O23: =G42 -> 0.049201402
A24: Name | B24: Units | C24: Value | E24: Flat Plate Conduction Resistance of top half of heat block | I24: Total Bottom Heat Out | J24: W | K24: =(K21-K22)/K23 -> 0.04057275 | M24: Total Top Heat Out | N24: W | O24: =K29 -> 3.8592056
A25: Nozzle Dimensions (Modelled as Cylinder) | E25: Thermal Conducitvity of Aluminium | F25: W/mK | G25: =C9 -> 155.3 | I25: Total Heat Out through the Top | M25: Bottom of Heat Sink Temperature | N25: K | O25: =O22+O23*O24 -> 494.629
A26: Inner Radius | B26: mm | C26: 1 | E26: Length | F26: m | G26: =C35/1000 -> 0.0075 | I26: Temperature of the Heater Cartridge | J26: K | K26: =C6+273 -> 503 | M26: Temperature at Top of Heat Block
A27: Outer Radius | B27: mm | C27: 3.5 | E27: Width | F27: m | G27: =C31/1000 -> 0.023 | I27: Temperature of the Ambient Air | J27: K | K27: =C7+273 -> 295 | M27: Bottom of Heat Sink Temperature | N27: K | O27: =O25 -> 494.629
A28: Length | B28: mm | C28: 6 | E28: Depth | F28: m | G28: =C32/1000 -> 0.016 | I28: Total Top Resistance | J28: K/W | K28: =K15 -> 53.897103 | M28: Conductive Heat Break Resistance | N28: K/W | O28: =G36 -> 2.0378678
A29: Heat Block Dimensions (Modelled as Flat Plate) | E29: Area | F29: m^2 | G29: =G27*G28 -> 0.000368 | I29: Total Top Heat Out | J29: W | K29: =(K26-K27)/K28 -> 3.8592056 | M29: Total Top Heat Out | N29: W | O29: =K29 -> 3.8592056
A30: Cross-sectional Area Values | E30: Conductive top half of heat block resistance | F30: K/W | G30: =G26/(G25*G29) -> 0.13123268 | M30: Top of Heat Block Temperature | N30: K | O30: =O27+O28*O29 -> 502.49355
A31: Width | B31: mm | C31: 23 | E31: Cylindrical Conduction Resistance of Heat Break | I31: Total Heat Out (Filament)
A32: Depth | B32: mm | C32: 16 | E32: Inner Radius | F32: m | G32: =C37/1000 -> 0.001
A33: Lengths | E33: Outer Radius | F33: m | G33: =C38/1000 -> 0.00148 | I33: Mass Flowrate of PLA
A34: Length from center of heater cartridge to bottom | B34: mm | C34: 4 | E34: Length | F34: m | G34: =C39/1000 -> 0.0021 | I34: Density of PLA | J34: kg/m^3 | K34: =C16 -> 1240
A35: Length from center of heater cartridge to top | B35: mm | C35: 7.5 | E35: Thermal Conducitvity of Stainless Steel | F35: W/mK | G35: =C11 -> 14.58 | I35: Volumetric Flow Rate of PLA | J35: m^3/s | K35: =C17/10^9 -> 1.5e-08
A36: Heat Break Dimensions (Modelled as Cylinder) | E36: Conductive Heat Break Resistance | F36: K/W | G36: =LN((G33/G32))/(2*pi()*G34*G35) -> 2.0378678 | I36: Mass Flowrate | J36: kg/s | K36: =K35*K34 -> 1.86e-05
A37: Inner Radius | B37: mm | C37: 1 | E37: Cylindrical Conduction Resistance of Heat Sink | I37: Total Heat Out through Filament
A38: Outer Radius | B38: mm | C38: 1.48 | E38: Inner Radius | F38: m | G38: =C41/1000 -> 0.0028 | I38: Mass Flowrate | J38: kg/s | K38: =K36 -> 1.86e-05
A39: Length | B39: mm | C39: 2.1 | E39: Outer Radius | F39: m | G39: =C42/1000 -> 0.011 | I39: Specifc Heat Capacity of PLA | J39: J/kgK | K39: =C18 -> 1800
A40: Heat Sink Dimensions (Modelled as Cylinder) | E40: Length | F40: m | G40: =C43/1000 -> 0.0285 | I40: Temperature Unheated PLA | J40: K | K40: =C19+273 -> 333
A41: Inner Radius | B41: mm | C41: =average(2.1,3.5) -> 2.8 | E41: Thermal Conducitvity of Aluminium | F41: W/mK | G41: =C9 -> 155.3 | I41: Temperature Heated PLA | J41: K | K41: =C20+273 -> 503
A42: Outer Radius | B42: mm | C42: 11 | E42: Conductive Heat Sink Resistance | F42: K/W | G42: =LN((G39/G38))/(2*pi()*G40*G41) -> 0.049201402 | I42: Total Filament Heat Out | J42: W | K42: =K38*K39*(K41-K40) -> 5.6916
...

Sheet Solution 2
A2: Initial Inputs | E2: Individiual Resistance | I2: Total Resistance | M2: Temperature at Different Points | Q2: Final Values Summary
A4: Name | B4: Units | C4: Value | E4: Name | F4: Units | G4: Value | I4: Name | J4: Units | K4: Value | M4: Name | N4: Units | O4: Value | Q4: Name | R4: Units | S4: Value
A5: Initial Temperatures | E5: Natural Convection Resistance between Nozzle and Ambient Air | I5: Total Resistance through the Bottom | M5: Temperature at Bottom of Nozzle | Q5: Heat Balance
A6: Temperature of the Heater Cartridge | B6: C | C6: 230 | E6: Natural Convective Air Heat Transfer Coefficient | F6: W/m^2K | G6: =C13 -> 8.88 | I6: Convective Nozzle Resistance | J6: K/W | K6: =G10 -> 3186.2851 | M6: Temperature of the Ambient Air | N6: K | O6: =C7+273 -> 295 | Q6: Total Heat In | R6: W | S6: =K73 -> 5.9040977
A7: Temperature of the Ambient AIr | B7: C | C7: 22 | E7: Inner Radius | F7: m | G7: =C26/1000 -> 0.001 | I7: Conductive Nozzle Resistance | J7: K/W | K7: =G16 -> 0.29643684 | M7: Convective Nozzle Resistance | N7: K/W | O7: =G10 -> 3186.2851 | Q7: Total Heat Out through Bottom | R7: W | S7: =K46 -> 0.065272276
A8: Thermal Conductivity | E8: Outer Radius | F8: m | G8: =C27/1000 -> 0.0035 | I8: Conductive bottom half of heat block resistance | J8: K/W | K8: =G23 -> 0.069990761 | M8: Total Bottom Heat Out | N8: W | O8: =K46 -> 0.065272276 | Q8: Total Heat Out through Top | R8: W | S8: =K51 -> 0.14722542
A9: Alumnium | B9: W/mK | C9: 155.3 | E9: Area of nozzle | F9: m^2 | G9: =pi()*(G8^2-G7^2) -> 3.5342917e-05 | I9: Total Bottom Resistance | J9: K/W | K9: =SUM(K6:K8) -> 3186.6516 | M9: Bottom of Nozzle Temperature | N9: K | O9: =O6+O7*O8 -> 502.97608 | Q9: Total Heat Out through Filament | R9: W | S9: =K64 -> 5.6916
A10: Brass | B10: W/mK | C10: 112.1 | E10: Convective Nozzle Resistance | F10: K/W | G10: =1/(G6*G9) -> 3186.2851 | I10: Total Resistance through the Top | M10: Temperature at Bottom of Heat Block | Q10: Check | S10: =S6-SUM(S7:S9) -> 0
A11: Stainless Steel | B11: W/mK | C11: 14.58 | E11: Cylindrical Conduction Resistance of Nozzle | I11: Conductive top half of heat block resistance | J11: K/W | K11: =G30 -> 0.13123268 | M11: Bottom of Nozzle Temperature | N11: K | O11: =O9 -> 502.97608
A12: Convective Heat Transfer Coefficient | E12: Inner Radius | F12: m | G12: =C26/1000 -> 0.001 | I12: Conductive Heat Break Resistance | J12: K/W | K12: =G36 -> 2.0378678 | M12: Conductive Nozzle Resistance | N12: K/W | O12: =G16 -> 0.29643684 | Q12: Name | R12: Units | S12: Value
A13: Natural Air | B13: W/m^2K | C13: 8.88 | E13: Outer Radius | F13: m | G13: =C27/1000 -> 0.0035 | I13: Conductive Heat Sink Resistance Fin 1 | J13: K/W | K13: =$G$42 -> 1.40224 | M13: Total Bottom Heat Out | N13: W | O13: =K46 -> 0.065272276 | Q13: Temperature Values
A14: Forced Air (from Fan) | B14: W/m^2K | C14: 26.1 | E14: Length | F14: m | G14: =C28/1000 -> 0.006 | I14: Convective Heat Sink Resistance Gap 1 | J14: K/W | K14: =$G$48 -> 116.1503 | M14: Bottom of Heat Block Temperature | N14: K | O14: =O11+O12*O13 -> 502.99543 | Q14: Ambient Temperature | R14: C | S14: =C7 -> 22
A15: PLA Properties | E15: Thermal Conducitvity of Brass | F15: W/mK | G15: =C10 -> 112.1 | I15: Conductive Heat Sink Resistance Fin 2 | J15: K/W | K15: =$G$42 -> 1.40224 | Q15: Bottom of Nozzle Temperature | R15: C | S15: =O9-273 -> 229.97608
A16: Density of PLA | B16: kg/m^3 | C16: 1240 | E16: Conductive Nozzle Resistance | F16: K/W | G16: =LN((G13/G12))/(2*pi()*G14*G15) -> 0.29643684 | I16: Convective Heat Sink Resistance Gap 2 | J16: K/W | K16: =$G$48 -> 116.1503 | M16: Temperature at Top of Heat Sink - TF24 | Q16: Bottom of Heat Block Temperature | R16: C | S16: =O14-273 -> 229.99543
A17: Estimated Volumetric Flow Rate of PLA | B17: mm^3/s | C17: 15 | E17: Flat Plate Conduction Resistance of bottom half of heat block | I17: Conductive Heat Sink Resistance Fin 3 | J17: K/W | K17: =$G$42 -> 1.40224 | M17: Temperature of the Ambient Air | N17: K | O17: =C7+273 -> 295 | Q17: Heater Cartridge Temperature | R17: C | S17: =C6 -> 230
A18: Specific Heat Capacity of PLA | B18: J/kgK | C18: 1800 | E18: Thermal Conducitvity of Aluminium | F18: W/mK | G18: =C9 -> 155.3 | I18: Convective Heat Sink Resistance Gap 3 | J18: K/W | K18: =$G$48 -> 116.1503 | M18: Convective Heat Sink Resistance per Fin | N18: K/W | O18: =G48 -> 116.1503 | Q18: Top of Heat Block Temperature | R18: C | S18: =O59-273 -> 229.98068
A19: Temperature of unheated PLA | B19: C | C19: 60 | E19: Length | F19: m | G19: =C34/1000 -> 0.004 | I19: Conductive Heat Sink Resistance Fin 4 | J19: K/W | K19: =$G$42 -> 1.40224 | M19: Total Top Heat Out | N19: W | O19: =K51 -> 0.14722542 | Q19: TF1 - Bottom of Heat Sink | R19: C | S19: =O54-273 -> 229.68065
A20: Temperature of heated PLA | B20: C | C20: 230 | E20: Width | F20: m | G20: =C31/1000 -> 0.023 | I20: Convective Heat Sink Resistance Gap 4 | J20: K/W | K20: =$G$48 -> 116.1503 | M20: Top of Heat Sink Temperature - TF24 | N20: K | O20: =O17+O18*O19 -> 312.10028 | Q20: TF2 | R20: C | S20: =O48-273 -> 229.47421
E21: Depth | F21: m | G21: =C32/1000 -> 0.016 | I21: Conductive Heat Sink Resistance Fin 5 | J21: K/W | K21: =$G$42 -> 1.40224 | Q21: TF3 | R21: C | S21: =O47-273 -> 212.37393
A22: Dimensions | E22: Area | F22: m^2 | G22: =G21*G20 -> 0.000368 | I22: Convective Heat Sink Resistance Gap 5 | J22: K/W | K22: =$G$48 -> 116.1503 | M22: Temperature of all the Fins | Q22: TF4 | R22: C | S22: =O46-273 -> 212.16749
E23: Conductive bottom half of heat block resistance | F23: K/W | G23: =G19/(G18*G22) -> 0.069990761 | I23: Conductive Heat Sink Resistance Fin 6 | J23: K/W | K23: =$G$42 -> 1.40224 | M23: Conductive Heat Sink Resistance per Fin | N23: K/W | O23: =G42 -> 1.40224 | Q23: TF5 | R23: C | S23: =O45-273 -> 195.06721
A24: Name | B24: Units | C24: Value | E24: Flat Plate Conduction Resistance of top half of heat block | I24: Convective Heat Sink Resistance Gap 6 | J24: K/W | K24: =$G$48 -> 116.1503 | M24: Convective Heat Sink Resistance per Fin | N24: K/W | O24: =G48 -> 116.1503 | Q24: TF6 | R24: C | S24: =O44-273 -> 194.86077
A25: Nozzle Dimensions (Modelled as Cylinder) | E25: Thermal Conducitvity of Aluminium | F25: W/mK | G25: =C9 -> 155.3 | I25: Conductive Heat Sink Resistance Fin 7 | J25: K/W | K25: =$G$42 -> 1.40224 | M25: Total Top Heat Out | N25: W | O25: =K51 -> 0.14722542 | Q25: TF7 | R25: C | S25: =O43-273 -> 177.76049
A26: Inner Radius | B26: mm | C26: 1 | E26: Length | F26: m | G26: =C35/1000 -> 0.0075 | I26: Convective Heat Sink Resistance Gap 7 | J26: K/W | K26: =$G$48 -> 116.1503 | M26: Top of Heat Sink Temperature - TF24 | N26: K | O26: =O20 -> 312.10028 | Q26: TF8 | R26: C | S26: =O42-273 -> 177.55404
A27: Outer Radius | B27: mm | C27: 3.5 | E27: Width | F27: m | G27: =C31/1000 -> 0.023 | I27: Conductive Heat Sink Resistance Fin 8 | J27: K/W | K27: =$G$42 -> 1.40224 | M27: TF23 | N27: K | O27: =O26+$O$25*$O$23 -> 312.30672 | Q27: TF9 | R27: C | S27: =O41-273 -> 160.45377
A28: Length | B28: mm | C28: 6 | E28: Depth | F28: m | G28: =C32/1000 -> 0.016 | I28: Convective Heat Sink Resistance Gap 8 | J28: K/W | K28: =$G$48 -> 116.1503 | M28: TF22 | N28: K | O28: =O27+$O$25*$O$24 -> 329.407 | Q28: TF10 | R28: C | S28: =O40-273 -> 160.24732
A29: Heat Block Dimensions (Modelled as Flat Plate) | E29: Area | F29: m^2 | G29: =G27*G28 -> 0.000368 | I29: Conductive Heat Sink Resistance Fin 9 | J29: K/W | K29: =$G$42 -> 1.40224 | M29: TF21 | N29: K | O29: =O28+$O$25*$O$23 -> 329.61344 | Q29: TF11 | R29: C | S29: =O39-273 -> 143.14705
A30: Cross-sectional Area Values | E30: Conductive top half of heat block resistance | F30: K/W | G30: =G26/(G25*G29) -> 0.13123268 | I30: Convective Heat Sink Resistance Gap 9 | J30: K/W | K30: =$G$48 -> 116.1503 | M30: TF20 | N30: K | O30: =O29+$O$25*$O$24 -> 346.71372 | Q30: TF12 | R30: C | S30: =O38-273 -> 142.9406
A31: Width | B31: mm | C31: 23 | E31: Cylindrical Conduction Resistance of Heat Break | I31: Conductive Heat Sink Resistance Fin 10 | J31: K/W | K31: =$G$42 -> 1.40224 | M31: TF19 | N31: K | O31: =O30+$O$25*$O$23 -> 346.92016 | Q31: TF13 | R31: C | S31: =O37-273 -> 125.84033
A32: Depth | B32: mm | C32: 16 | E32: Inner Radius | F32: m | G32: =C37/1000 -> 0.001 | I32: Convective Heat Sink Resistance Gap 10 | J32: K/W | K32: =$G$48 -> 116.1503 | M32: TF18 | N32: K | O32: =O31+$O$25*$O$24 -> 364.02044 | Q32: TF14 | R32: C | S32: =O36-273 -> 125.63388
A33: Lengths | E33: Outer Radius | F33: m | G33: =C38/1000 -> 0.00148 | I33: Conductive Heat Sink Resistance Fin 11 | J33: K/W | K33: =$G$42 -> 1.40224 | M33: TF17 | N33: K | O33: =O32+$O$25*$O$23 -> 364.22688 | Q33: TF15 | R33: C | S33: =O35-273 -> 108.53361
A34: Length from center of heater cartridge to bottom | B34: mm | C34: 4 | E34: Length | F34: m | G34: =C39/1000 -> 0.0021 | I34: Convective Heat Sink Resistance Gap 11 | J34: K/W | K34: =$G$48 -> 116.1503 | M34: TF16 | N34: K | O34: =O33+$O$25*$O$24 -> 381.32716 | Q34: TF16 | R34: C | S34: =O34-273 -> 108.32716
A35: Length from center of heater cartridge to top | B35: mm | C35: 7.5 | E35: Thermal Conducitvity of Stainless Steel | F35: W/mK | G35: =C11 -> 14.58 | I35: Conductive Heat Sink Resistance Fin 12 | J35: K/W | K35: =$G$42 -> 1.40224 | M35: TF15 | N35: K | O35: =O34+$O$25*$O$23 -> 381.53361 | Q35: TF17 | R35: C | S35: =O33-273 -> 91.226884
A36: Heat Break Dimensions (Modelled as Cylinder) | E36: Conductive Heat Break Resistance | F36: K/W | G36: =LN((G33/G32))/(2*pi()*G34*G35) -> 2.0378678 | I36: Convective Heat Sink Resistance Gap 12 | J36: K/W | K36: =$G$48 -> 116.1503 | M36: TF14 | N36: K | O36: =O35+$O$25*$O$24 -> 398.63388 | Q36: TF18 | R36: C | S36: =O32-273 -> 91.020439
A37: Inner Radius | B37: mm | C37: 1 | E37: Cylindrical Conduction Resistance through each Fin of Heat Sink | I37: Total Top Resistance | J37: K/W | K37: =SUM(K11:K36) -> 1412.7995 | M37: TF13 | N37: K | O37: =O36+$O$25*$O$23 -> 398.84033 | Q37: TF19 | R37: C | S37: =O31-273 -> 73.920163
A38: Outer Radius | B38: mm | C38: 1.48 | E38: Inner Radius | F38: m | G38: =C41/1000 -> 0.0028 | M38: TF12 | N38: K | O38: =O37+$O$25*$O$24 -> 415.9406 | Q38: TF20 | R38: C | S38: =O30-273 -> 73.713718
A39: Length | B39: mm | C39: 2.1 | E39: Outer Radius | F39: m | G39: =C43/1000 -> 0.011 | I39: Total Heat Out (except Filament) | M39: TF11 | N39: K | O39: =O38+$O$25*$O$23 -> 416.14705 | Q39: TF21 | R39: C | S39: =O29-273 -> 56.613442
A40: Heat Sink Dimensions (Modelled as Cylinder) | E40: Length | F40: m | G40: =C44/1000 -> 0.001 | M40: TF10 | N40: K | O40: =O39+$O$25*$O$24 -> 433.24732 | Q40: TF22 | R40: C | S40: =O28-273 -> 56.406997
A41: Inner Radius | B41: mm | C41: =average(2.1,3.5) -> 2.8 | E41: Thermal Conducitvity of Aluminium | F41: W/mK | G41: =C9 -> 155.3 | I41: Name | J41: Units | K41: Value | M41: TF09 | N41: K | O41: =O40+$O$25*$O$23 -> 433.45377 | Q41: TF23 | R41: C | S41: =O27-273 -> 39.306721
A42: Middle Radius | B42: mm | C42: 4 | E42: Conductive Heat Sink Resistance per Fin | F42: K/W | G42: =LN((G39/G38))/(2*pi()*G40*G41) -> 1.40224 | I42: Total Heat Out through the Bottom | M42: TF08 | N42: K | O42: =O41+$O$25*$O$24 -> 450.55404 | Q42: TF24 - Top of Heat Sink | R42: C | S42: =O26-273 -> 39.100276
...

Sheet Solution 3
A2: Initial Inputs | E2: Individiual Resistance | I2: Total Resistance | M2: Temperature at Different Points | Q2: Final Values Summary
A4: Name | B4: Units | C4: Value | E4: Name | F4: Units | G4: Value | I4: Name | J4: Units | K4: Value | M4: Name | N4: Units | O4: Value | Q4: Name | R4: Units | S4: Value
A5: Initial Temperatures | I5: Total Resistance through the Bottom | M5: Temperature at Bottom of Nozzle | Q5: Heat Balance
A6: Temperature of the Heater Cartridge | B6: C | C6: 230 | E6: In Series Convection and Conduction of Nozzle | I6: In Series Convection and Conduction of Nozzle outside heatblock | J6: K/W | K6: =G20 -> 5126.5236 | M6: Temperature of the Ambient Air | N6: K | O6: =C7+273 -> 295 | Q6: Total Heat In | R6: W | S6: =K73 -> 22.007531
A7: Temperature of the Ambient AIr | B7: C | C7: 22 | I7: In Parallel Conduction of Brass and Aluminium in Bottom Section of Heat Block | J7: K/W | K7: =G39 -> 0.063474577 | M7: Natural Convective Nozzle Resistance Outside of Heat Block | N7: K/W | O7: =G13 -> 5126.2271 | Q7: Total Heat Out through Bottom | R7: W | S7: =K46 -> 0.040572802
A8: Thermal Conductivity | E8: Natural Convection Resistance between Nozzle and Ambient Air | I8: Total Bottom Resistance | J8: K/W | K8: =SUM(K6:K7) -> 5126.587 | M8: Total Bottom Heat Out | N8: W | O8: =K46 -> 0.040572802 | Q8: Total Heat Out through Top | R8: W | S8: =K51 -> 16.275358
A9: Alumnium | B9: W/mK | C9: 155.3 | E9: Natural Convective Bottom Air Heat Transfer Coefficient | F9: W/m^2K | G9: =C14 -> 5.5195003 | I9: Total Resistance through the Top | M9: Bottom of Nozzle Temperature | N9: K | O9: =O6+O7*O8 -> 502.9854 | Q9: Total Heat Out through Filament | R9: W | S9: =K64 -> 5.6916
A10: Brass | B10: W/mK | C10: 112.1 | E10: Inner Radius | F10: m | G10: =C27/1000 -> 0.001 | I10: In Parallel Conduction of Brass and Aluminium in Middle Section of Heat Block | J10: K/W | K10: =G58 -> 0.044040127 | M10: Temperature at Bottom of Heat Block | Q10: Check | S10: =S6-SUM(S7:S9) -> 0
A11: Stainless Steel | B11: W/mK | C11: 14.58 | E11: Outer Radius | F11: m | G11: =C28/1000 -> 0.0035 | I11: In Parallel Conduction of Steel and Aluminium in Top Section of Heat Block | J11: K/W | K11: =G77 -> 0.091167601 | M11: Bottom of Nozzle Temperature | N11: K | O11: =O9 -> 502.9854
A12: Convective Heat Transfer Coefficient | E12: Area of nozzle | F12: m^2 | G12: =pi()*(G11^2-G10^2) -> 3.5342917e-05 | I12: In Parallel Conduction of Steel and Convection through neck of Heat Break | J12: K/W | K12: =G95 -> 2.0311348 | M12: Conductive Nozzle Resistance Outside of Heat Block | N12: K/W | O12: =G19 -> 0.29643684 | Q12: Name | R12: Units | S12: Value
A13: Natural Air at top of heat block | B13: W/m^2K | C13: ='Natural and Forced Convection C'!S5 -> 4.5045031 | E13: Natural Convective Nozzle Resistance Outside of Heat Block | F13: K/W | G13: =1/(G9*G12) -> 5126.2271 | I13: In Parallel Conduction of Steel and Aluminium through each Fin 1 | J13: K/W | K13: =G129 -> 0.84788501 | M13: Total Bottom Heat Out | N13: W | O13: =K46 -> 0.040572802 | Q13: Temperature Values
A14: Natural Air at bottom of nozzle | B14: W/m^2K | C14: ='Natural and Forced Convection C'!S6 -> 5.5195003 | E14: Cylindrical Conduction Resistance of Nozzle | I14: In Parallel Condunction of Steel and Aluminium and Convection through Gap 1 | J14: K/W | K14: =G130 -> 0.00036551636 | M14: Bottom of Heat Block Temperature | N14: K | O14: =O11+O12*O13 -> 502.99742 | Q14: Ambient Temperature | R14: C | S14: =C7 -> 22
A15: Forced Air (from Fan) | B15: W/m^2K | C15: ='Natural and Forced Convection C'!S7 -> 54.430806 | E15: Inner Radius | F15: m | G15: =C27/1000 -> 0.001 | I15: In Parallel Conduction of Steel and Aluminium through each Fin 2 | J15: K/W | K15: =G129 -> 0.84788501 | Q15: Bottom of Nozzle Temperature | R15: C | S15: =O9-273 -> 229.9854
A16: PLA Properties | E16: Outer Radius | F16: m | G16: =C28/1000 -> 0.0035 | I16: In Parallel Condunction of Steel and Aluminium and Convection through Gap 2 | J16: K/W | K16: =G130 -> 0.00036551636 | M16: Temperature at Top of Heat Sink - TF24 | Q16: Bottom of Heat Block Temperature | R16: C | S16: =O14-273 -> 229.99742
A17: Density of PLA | B17: kg/m^3 | C17: 1240 | E17: Length | F17: m | G17: =C29/1000 -> 0.006 | I17: In Parallel Conduction of Steel and Aluminium through each Fin 3 | J17: K/W | K17: =G129 -> 0.84788501 | M17: Temperature of the Ambient Air | N17: K | O17: =C7+273 -> 295 | Q17: Heater Cartridge Temperature | R17: C | S17: =C6 -> 230
A18: Estimated Volumetric Flow Rate of PLA | B18: mm^3/s | C18: 15 | E18: Thermal Conducitvity of Brass | F18: W/mK | G18: =C10 -> 112.1 | I18: In Parallel Condunction of Steel and Aluminium and Convection through Gap 3 | J18: K/W | K18: =G130 -> 0.00036551636 | M18: Heat Sink Resistance per Gap for top 6 | N18: K/W | O18: =K36 -> 0.00036552613 | Q18: Bottom of Heat Break Temperature | R18: C | S18: =O66-273 -> 229.28323
A19: Specific Heat Capacity of PLA | B19: J/kgK | C19: 1800 | E19: Conductive Nozzle Resistance Outside of Heat Block | F19: K/W | G19: =LN((G16/G15))/(2*pi()*G17*G18) -> 0.29643684 | I19: In Parallel Conduction of Steel and Aluminium through each Fin 4 | J19: K/W | K19: =G129 -> 0.84788501 | M19: Total Top Heat Out | N19: W | O19: =K51 -> 16.275358 | Q19: Top of Heat Block Temperature | R19: C | S19: =O61-273 -> 227.79945
A20: Temperature of unheated PLA | B20: C | C20: 60 | E20: In Series Convection and Conduction of Nozzle outside heatblock | G20: =G13+G19 -> 5126.5236 | I20: In Parallel Condunction of Steel and Aluminium and Convection through Gap 4 | J20: K/W | K20: =G130 -> 0.00036551636 | M20: Top of Heat Sink Temperature - TF24 | N20: K | O20: =O17+O18*O19 -> 295.00595 | Q20: TF1 - Bottom of Heat Sink | R20: C | S20: =O56-273 -> 194.742
A21: Temperature of heated PLA | B21: C | C21: 230 | I21: In Parallel Conduction of Steel and Aluminium through each Fin 5 | J21: K/W | K21: =G129 -> 0.84788501 | Q21: TF2 | R21: C | S21: =O50-273 -> 180.94237
E22: In Parallel Conduction of Brass and Aluminium in Bottom Section of Heat Block | I22: In Parallel Condunction of Steel and Aluminium and Convection through Gap 5 | J22: K/W | K22: =G130 -> 0.00036551636 | M22: Temperature of all the Fins | Q22: TF3 | R22: C | S22: =O49-273 -> 180.93642
A23: Dimensions | I23: In Parallel Conduction of Steel and Aluminium through each Fin 6 | J23: K/W | K23: =G129 -> 0.84788501 | M23: Heat Sink Resistance per Fin for Top 5 | N23: K/W | O23: =K35 -> 0.93482664 | Q23: TF4 | R23: C | S23: =O48-273 -> 167.13679
E24: Cylindrical Conduction Resistance of Brass in Heat Block | I24: In Parallel Condunction of Steel and Aluminium and Convection through Gap 6 | J24: K/W | K24: =G130 -> 0.00036551636 | M24: Heat Sink Resistance per Gap for Top 6 | N24: K/W | O24: =K36 -> 0.00036552613 | Q24: TF5 | R24: C | S24: =O47-273 -> 167.13084
A25: Name | B25: Units | C25: Value | E25: Inner Radius | F25: m | G25: =C31/1000 -> 0.001 | I25: In Parallel Conduction of Steel and Aluminium through each Fin 7 | J25: K/W | K25: =G129 -> 0.84788501 | M25: Heat Sink Resistance per Fin for Top 7 | N25: K/W | O25: =K25 -> 0.84788501 | Q25: TF6 | R25: C | S25: =O46-273 -> 153.33121
A26: Nozzle Dimensions Outside of Heat Block (Modelled as Cylinder) | E26: Outer Radius | F26: m | G26: =C32/1000 -> 0.003 | I26: In Parallel Conduction of Aluminium and Convection through the Gap 7 | J26: K/W | K26: =G132 -> 0.00036552613 | M26: Heat Sink Resistance per Gap for Top 6 | N26: K/W | O26: =K24 -> 0.00036551636 | Q26: TF7 | R26: C | S26: =O45-273 -> 153.32526
A27: Inner Radius | B27: mm | C27: 1 | E27: Length of bottom section | F27: m | G27: =C37/1000 -> 0.004 | I27: Conduction of Aluminium through Fin 8 | J27: K/W | K27: =G131 -> 0.93482664 | M27: Total Top Heat Out | N27: W | O27: =K51 -> 16.275358 | Q27: TF8 | R27: C | S27: =O44-273 -> 139.52563
A28: Outer Radius | B28: mm | C28: 3.5 | E28: Thermal Conducitvity of Brass | F28: W/mK | G28: =C10 -> 112.1 | I28: In Parallel Conduction of Aluminium and Convection through the Gap 8 | J28: K/W | K28: =G132 -> 0.00036552613 | M28: Top of Heat Sink Temperature - TF24 | N28: K | O28: =O20 -> 295.00595 | Q28: TF9 | R28: C | S28: =O43-273 -> 139.51968
